test_chronos1 (__main__.TestTime) ... ok
test_chronos2 (__main__.TestTime) ... FAIL

======================================================================
FAIL: test_chronos2 (__main__.TestTime)
----------------------------------------------------------------------
Traceback (most recent call last):
  File "test_timecalc.py", line 16, in test_chronos2
    self.assertEqual(expected, result)
AssertionError: 15 != 12

----------------------------------------------------------------------
Ran 2 tests in 0.000s

FAILED (failures=1)
